Workbook
Name Slicer_Destination: #N/A
Name Slicer_RouteCode: #N/A

Sheet Dashboard
A2: FLIGHTS | D2: REVENUE | G2: SEATS SOLD | J2: Cost | M2: PROFIT MARGIN
A3: =COUNTA(Database!A1:A1000) -> 1000 | D3: =SUM(Database!J2:J1000) -> 673574543 | G3: =SUM(Database!I1:I1000) -> 93066 | J3: =SUM(Database!K1:K1000) -> 54791454 | M3: =SUM(Database!L1:L1000)/SUM(Database!J1:J1000) -> #REF!
A4: Total Flights | D4: Total Revenue | G4: Total Seats Sold | J4: Total Operational Cost | M4: Profit / revenue

Sheet Pivort Tables
A1: Row Labels | B1: Sum of Revenue | D1: Row Labels | E1: Sum of Profit | G1: Row Labels | H1: Sum of Profit | J1: Row Labels | K1: Sum of OperationalCost | L1: Sum of Revenue | N1: Values
A2: HYD | B2: 75310803 | D2: AMD-BLR | E2: 8504587 | G2: Jan | H2: 53213807 | J2: AMD-BLR | K2: 859000 | L2: 9363587 | N2: Sum of SeatsAvailable | O2: 143505
A3: Grand Total | B3: 75310803 | D3: DEL-BLR | E3: 7433526 | G3: Feb | H3: 41150779 | J3: AMD-BOM | K3: 877727 | L3: 9739363 | N3: Sum of SeatsSold | O3: 93066
D4: JAI-BLR | E4: 7052586 | G4: Mar | H4: 57914675 | J4: AMD-CCU | K4: 672588 | L4: 9199331
D5: PNQ-BLR | E5: 6594875 | G5: Apr | H5: 64342211 | J5: AMD-DEL | K5: 521771 | L5: 5596329
D6: GOI-BLR | E6: 6376067 | G6: May | H6: 60761299 | J6: AMD-GOI | K6: 694206 | L6: 9256912
D7: CCU-BLR | E7: 4621961 | G7: Jun | H7: 39884972 | J7: AMD-HYD | K7: 379872 | L7: 6678355
D8: BOM-BLR | E8: 4246722 | G8: Jul | H8: 50525059 | J8: AMD-JAI | K8: 377682 | L8: 6872963
D9: MAA-BLR | E9: 3133978 | G9: Aug | H9: 46265909 | J9: AMD-MAA | K9: 397375 | L9: 5500101
D10: HYD-BLR | E10: 2688185 | G10: Sep | H10: 49015944 | J10: AMD-PNQ | K10: 876312 | L10: 10546333
D11: Grand Total | E11: 50652487 | G11: Oct | H11: 47949515 | J11: BLR-AMD | K11: 453243 | L11: 5789107
G12: Nov | H12: 49800262 | J12: BLR-BOM | K12: 463343 | L12: 5104671
G13: Dec | H13: 58525263 | J13: BLR-CCU | K13: 880443 | L13: 11109986
G14: Grand Total | H14: 619349695 | J14: BLR-DEL | K14: 917323 | L14: 11614082
J15: BLR-GOI | K15: 988740 | L15: 12430327
J16: BLR-HYD | K16: 787751 | L16: 9792730
J17: BLR-JAI | K17: 856645 | L17: 10512259
J18: BLR-MAA | K18: 477643 | L18: 7497052
J19: BLR-PNQ | K19: 290505 | L19: 4443615
J20: BOM-AMD | K20: 643103 | L20: 8145682
J21: BOM-BLR | K21: 406707 | L21: 4653429
J22: BOM-CCU | K22: 367338 | L22: 3790877
J23: BOM-DEL | K23: 390950 | L23: 8707186
J24: BOM-GOI | K24: 530071 | L24: 6649271
J25: BOM-HYD | K25: 570378 | L25: 9256092
J26: BOM-JAI | K26: 596255 | L26: 7596620
... J92: Grand Total | K92: 54830903 | L92: 674180598

Sheet Queries-Output
A2: 1. List top 10 most frequent routes based on number of flights. | H2: -- 2.Calculate average revenue, cost, and profit per route. | M2: 3.Identify underperforming routes where average profit is negative | S2: 4. Calculate seat occupancy % for each route. | Z2: 5.Extract monthly trend of profit per route. | AF2: 6. Compare profitability of domestic vs international routes.
AJ3: 7. Rank routes based on revenue per minute of flight duration.
A4: HYD | B4: DEL | C4: 19 | H4: BOM-DEL | I4: 1088398.2 | J4: 48868.75 | K4: 1039529.5 | M4: No Output | S4: CCU-JAI | T4: 872 | U4: 1087 | V4: 80.22 | Z4: AMD-BLR | AA4: 8504587 | AF4: International | AG4: 1000 | AH4: 619349695 | AJ4: BOM-DEL | AK4: 9041.73
A5: PNQ | B5: GOI | C5: 19 | H5: CCU-AMD | I5: 1014146.8 | J5: 57086.4 | K5: 957060.4 | S5: GOI-JAI | T5: 684 | U5: 864 | V5: 79.17 | Z5: AMD-BOM | AA5: 8861636 | AJ5: AMD-HYD | AK5: 8810.49
A6: HYD | B6: AMD | C6: 18 | H6: AMD-JAI | I6: 981851.86 | J6: 53954.571 | K6: 927897.29 | S6: BLR-HYD | T6: 1373 | U6: 1758 | V6: 78.1 | Z6: AMD-CCU | AA6: 8526743 | AJ6: CCU-AMD | AK6: 8326.33
A7: BLR | B7: CCU | C7: 17 | H7: JAI-CCU | I7: 991220.89 | J7: 65700.333 | K7: 925520.56 | S7: DEL-JAI | T7: 1240 | U7: 1626 | V7: 76.26 | Z7: AMD-DEL | AA7: 5074558 | AJ7: DEL-PNQ | AK7: 8162.21
A8: BLR | B8: DEL | C8: 17 | H8: DEL-PNQ | I8: 974023.33 | J8: 57028.444 | K8: 916994.89 | S8: BLR-PNQ | T8: 515 | U8: 682 | V8: 75.51 | Z8: AMD-GOI | AA8: 8562706 | AJ8: MAA-DEL | AK8: 7030.9
A9: DEL | B9: GOI | C9: 17 | H9: MAA-DEL | I9: 867613.5 | J9: 55411.3 | K9: 812202.2 | S9: PNQ-AMD | T9: 1505 | U9: 2002 | V9: 75.17 | Z9: AMD-HYD | AA9: 6298483 | AJ9: AMD-JAI | AK9: 7027.57
A10: BLR | B10: GOI | C10: 17 | H10: PNQ-AMD | I10: 863753 | J10: 58750 | K10: 805003 | S10: AMD-JAI | T10: 844 | U10: 1138 | V10: 74.17 | Z10: AMD-JAI | AA10: 6495281 | AJ10: CCU-HYD | AK10: 6776.81
A11: DEL | B11: BOM | C11: 17 | H11: CCU-HYD | I11: 845068.6 | J11: 51082.1 | K11: 793986.5 | S11: BOM-DEL | T11: 914 | U11: 1237 | V11: 73.89 | Z11: AMD-MAA | AA11: 5102726 | AJ11: BOM-HYD | AK11: 6322.47
A12: GOI | B12: AMD | C12: 17 | H12: BOM-HYD | I12: 841462.91 | J12: 51852.546 | K12: 789610.36 | S12: AMD-CCU | T12: 1226 | U12: 1661 | V12: 73.81 | Z12: AMD-PNQ | AA12: 9670021 | AJ12: DEL-HYD | AK12: 6252.9
A13: PNQ | B13: CCU | C13: 16 | H13: AMD-HYD | I13: 834794.38 | J13: 47484 | K13: 787310.38 | S13: BLR-MAA | T13: 989 | U13: 1343 | V13: 73.64 | Z13: BLR-AMD | AA13: 5335864 | AJ13: PNQ-AMD | AK13: 6102.6
H14: GOI-CCU | I14: 828391.64 | J14: 60774.786 | K14: 767616.86 | S14: BOM-HYD | T14: 1234 | U14: 1682 | V14: 73.37 | Z14: BLR-BOM | AA14: 4641328 | AJ14: PNQ-CCU | AK14: 6082.42
H15: CCU-PNQ | I15: 806791.62 | J15: 52186.375 | K15: 754605.25 | S15: AMD-GOI | T15: 1314 | U15: 1807 | V15: 72.72 | Z15: BLR-CCU | AA15: 10229543 | AJ15: BLR-PNQ | AK15: 5988.7
H16: CCU-JAI | I16: 811453.12 | J16: 58439.5 | K16: 753013.62 | S16: MAA-DEL | T16: 1106 | U16: 1526 | V16: 72.48 | Z16: BLR-DEL | AA16: 10696759 | AJ16: JAI-CCU | AK16: 5789.09
H17: PNQ-BLR | I17: 795188.67 | J17: 62424.778 | K17: 732763.89 | S17: JAI-AMD | T17: 992 | U17: 1375 | V17: 72.15 | Z17: BLR-GOI | AA17: 11441587 | AJ17: CCU-PNQ | AK17: 5747.4
H18: JAI-BOM | I18: 773444.4 | J18: 56538 | K18: 716906.4 | S18: PNQ-BOM | T18: 1263 | U18: 1755 | V18: 71.97 | Z18: BLR-HYD | AA18: 9004979 | AJ18: PNQ-HYD | AK18: 5730.48
H19: AMD-GOI | I19: 771409.33 | J19: 57850.5 | K19: 713558.83 | S19: AMD-DEL | T19: 826 | U19: 1172 | V19: 70.48 | Z19: BLR-JAI | AA19: 9655614 | AJ19: CCU-JAI | AK19: 5709.43
H20: BLR-MAA | I20: 749705.2 | J20: 47764.3 | K20: 701940.9 | S20: GOI-PNQ | T20: 1189 | U20: 1688 | V20: 70.44 | Z20: BLR-MAA | AA20: 7019409 | AJ20: BLR-AMD | AK20: 5647.91
H21: CCU-BOM | I21: 755054.33 | J21: 53433.667 | K21: 701620.67 | S21: DEL-GOI | T21: 1784 | U21: 2544 | V21: 70.13 | Z21: BLR-PNQ | AA21: 4153110 | AJ21: GOI-HYD | AK21: 5576.75
H22: PNQ-HYD | I22: 740664.12 | J22: 46747.625 | K22: 693916.5 | S22: BLR-AMD | T22: 842 | U22: 1212 | V22: 69.47 | Z22: BOM-AMD | AA22: 7502579 | AJ22: HYD-BLR | AK22: 5452.91
H23: CCU-DEL | I23: 745914.73 | J23: 52641.333 | K23: 693273.4 | S23: MAA-HYD | T23: 1216 | U23: 1773 | V23: 68.58 | Z23: BOM-BLR | AA23: 4246722 | AJ23: CCU-BOM | AK23: 5313.13
H24: BLR-HYD | I24: 753286.92 | J24: 60596.231 | K24: 692690.69 | S24: GOI-DEL | T24: 587 | U24: 858 | V24: 68.41 | Z24: BOM-CCU | AA24: 3423539 | AJ24: BLR-MAA | AK24: 5268.48
H25: BLR-PNQ | I25: 740602.5 | J25: 48417.5 | K25: 692185 | S25: HYD-PNQ | T25: 944 | U25: 1382 | V25: 68.31 | Z25: BOM-DEL | AA25: 8316236 | AJ25: BLR-CCU | AK25: 5265.4
... H84: HYD-DEL | I84: 534870.32 | J84: 51408.105 | K84: 483462.21 | S84: BOM-MAA | T84: 599 | U84: 1058 | V84: 56.62 | Z84: MAA-PNQ | AA84: 5971335 | AJ84: BOM-PNQ | AK84: 3627.6
H85: PNQ-DEL | I85: 533658.44 | J85: 50940.889 | K85: 482717.56 | S85: JAI-DEL | T85: 450 | U85: 803 | V85: 56.04 | Z85: PNQ-AMD | AA85: 10465039 | AB85: S | AJ85: DEL-AMD | AK85: 3614.16
H86: PNQ-GOI | I86: 534119 | J86: 55016.789 | K86: 479102.21 | S86: MAA-CCU | T86: 749 | U86: 1364 | V86: 54.91 | Z86: PNQ-BLR | AA86: 6594875 | AJ86: MAA-JAI | AK86: 3554.79
H87: BOM-PNQ | I87: 519956.33 | J87: 50513.083 | K87: 469443.25 | S87: HYD-CCU | T87: 1034 | U87: 1884 | V87: 54.88 | Z87: PNQ-BOM | AA87: 6756456 | AJ87: HYD-JAI | AK87: 3487.26
H88: HYD-JAI | I88: 510749.54 | J88: 53626.385 | K88: 457123.15 | S88: PNQ-MAA | T88: 1170 | U88: 2149 | V88: 54.44 | Z88: PNQ-CCU | AA88: 10548652 | AJ88: PNQ-DEL | AK88: 3399.1
H89: HYD-MAA | I89: 482983.33 | J89: 50607.333 | K89: 432376 | S89: BOM-CCU | T89: 581 | U89: 1077 | V89: 53.95 | Z89: PNQ-DEL | AA89: 4344458 | AJ89: HYD-MAA | AK89: 3325.82
H90: DEL-JAI | I90: 482020.38 | J90: 57945.385 | K90: 424075 | S90: GOI-MAA | T90: 1177 | U90: 2231 | V90: 52.76 | Z90: PNQ-GOI | AA90: 9102942 | AJ90: DEL-JAI | AK90: 3040.4
H91: HYD-GOI | I91: 448683.75 | J91: 53318.25 | K91: 395365.5 | S91: GOI-BOM | T91: 1116 | U91: 2119 | V91: 52.67 | Z91: PNQ-HYD | AA91: 5551332 | AJ91: MAA-AMD | AK91: 2890.8
H92: MAA-AMD | I92: 407603.5 | J92: 64367 | K92: 343236.5 | S92: HYD-GOI | T92: 257 | U92: 542 | V92: 47.42 | Z92: PNQ-JAI | AA92: 7476420 | AJ92: JAI-DEL | AK92: 2890.59
H93: JAI-DEL | I93: 363388.14 | J93: 48077.857 | K93: 315310.29 | S93: MAA-AMD | T93: 592 | U93: 1407 | V93: 42.08 | Z93: PNQ-MAA | AA93: 7581668 | AJ93: HYD-GOI | AK93: 2694.8

Sheet Database
A1: FlightID | B1: RouteCode | C1: Origin | D1: Destination | E1: FlightDate | F1: FlightDurationMins | G1: AircraftType | H1: SeatsAvailable | I1: SeatsSold | J1: Revenue | K1: OperationalCost | L1: Profit | M1: Month | N1: Occcupies Seats | O1: Year Month
A2: FL00002 | B2: HYD-BOM | C2: HYD | D2: BOM | E2: 45688 | F2: 68 | G2: Boeing 737 | H2: 129 | I2: 104 | J2: 305136 | K2: 34654 | L2: =[1]!Table1[[#This Row],[Revenue]]-[1]!Table1[[#This Row],[OperationalCost]] -> #REF! | M2: =TEXT(E2,"MMM") -> Jan | N2: =Table11[[#This Row],[SeatsSold]]/Table11[[#This Row],[SeatsAvailable]] -> 0.80620155 | O2: 45658.229
A3: FL00003 | B3: GOI-HYD | C3: GOI | D3: HYD | E3: 45883 | F3: 159 | G3: Boeing 787 | H3: 141 | I3: 40 | J3: 204600 | K3: 73890 | L3: =[1]!Table1[[#This Row],[Revenue]]-[1]!Table1[[#This Row],[OperationalCost]] -> #REF! | M3: =TEXT(E3,"MMM") -> Aug | N3: =Table11[[#This Row],[SeatsSold]]/Table11[[#This Row],[SeatsAvailable]] -> 0.28368794 | O3: 45659.229
A4: FL00004 | B4: CCU-MAA | C4: CCU | D4: MAA | E4: 45817 | F4: 100 | G4: Airbus A321 | H4: 96 | I4: 45 | J4: 392580 | K4: 30816 | L4: =[1]!Table1[[#This Row],[Revenue]]-[1]!Table1[[#This Row],[OperationalCost]] -> #REF! | M4: =TEXT(E4,"MMM") -> Jun | N4: =Table11[[#This Row],[SeatsSold]]/Table11[[#This Row],[SeatsAvailable]] -> 0.46875 | O4: 45660.229
A5: FL00005 | B5: CCU-MAA | C5: CCU | D5: MAA | E5: 45702 | F5: 231 | G5: ATR 72 | H5: 207 | I5: 71 | J5: 617771 | K5: 78087 | L5: =[1]!Table1[[#This Row],[Revenue]]-[1]!Table1[[#This Row],[OperationalCost]] -> #REF! | M5: =TEXT(E5,"MMM") -> Feb | N5: =Table11[[#This Row],[SeatsSold]]/Table11[[#This Row],[SeatsAvailable]] -> 0.34299517 | O5: 45661.229 | P5: =TEXT(DATE(1900,1,1)+E2-2,"mmm yyyy hh:mm") -> Jan 2025 00:00
A6: FL00006 | B6: MAA-HYD | C6: MAA | D6: HYD | E6: 46249 | F6: 94 | G6: Airbus A320 | H6: 81 | I6: 54 | J6: 391014 | K6: 24419 | L6: =[1]!Table1[[#This Row],[Revenue]]-[1]!Table1[[#This Row],[OperationalCost]] -> #REF! | M6: =TEXT(E6,"MMM") -> Aug | N6: =Table11[[#This Row],[SeatsSold]]/Table11[[#This Row],[SeatsAvailable]] -> 0.66666667 | O6: 45662.229
A7: FL00007 | B7: DEL-PNQ | C7: DEL | D7: PNQ | E7: 45942 | F7: 161 | G7: Airbus A321 | H7: 111 | I7: 87 | J7: 723840 | K7: 44281 | L7: =[1]!Table1[[#This Row],[Revenue]]-[1]!Table1[[#This Row],[OperationalCost]] -> #REF! | M7: =TEXT(E7,"MMM") -> Oct | N7: =Table11[[#This Row],[SeatsSold]]/Table11[[#This Row],[SeatsAvailable]] -> 0.78378378 | O7: 45663.229
A8: FL00008 | B8: DEL-BLR | C8: DEL | D8: BLR | E8: 46204 | F8: 231 | G8: Boeing 737 | H8: 111 | I8: 99 | J8: 862884 | K8: 70632 | L8: =[1]!Table1[[#This Row],[Revenue]]-[1]!Table1[[#This Row],[OperationalCost]] -> #REF! | M8: =TEXT(E8,"MMM") -> Jul | N8: =Table11[[#This Row],[SeatsSold]]/Table11[[#This Row],[SeatsAvailable]] -> 0.89189189 | O8: 45664.229
A9: FL00009 | B9: GOI-BLR | C9: GOI | D9: BLR | E9: 46359 | F9: 128 | G9: Airbus A320 | H9: 128 | I9: 44 | J9: 337392 | K9: 47360 | L9: =[1]!Table1[[#This Row],[Revenue]]-[1]!Table1[[#This Row],[OperationalCost]] -> #REF! | M9: =TEXT(E9,"MMM") -> Dec | N9: =Table11[[#This Row],[SeatsSold]]/Table11[[#This Row],[SeatsAvailable]] -> 0.34375 | O9: 45665.229
A10: FL00010 | B10: DEL-MAA | C10: DEL | D10: MAA | E10: 46238 | F10: 228 | G10: Airbus A321 | H10: 124 | I10: 123 | J10: 1313517 | K10: 80644 | L10: =[1]!Table1[[#This Row],[Revenue]]-[1]!Table1[[#This Row],[OperationalCost]] -> #REF! | M10: =TEXT(E10,"MMM") -> Aug | N10: =Table11[[#This Row],[SeatsSold]]/Table11[[#This Row],[SeatsAvailable]] -> 0.99193548 | O10: 45666.229
A11: FL00011 | B11: PNQ-AMD | C11: PNQ | D11: AMD | E11: 45929 | F11: 80 | G11: Boeing 737 | H11: 213 | I11: 177 | J11: 1204308 | K11: 61777 | L11: =[1]!Table1[[#This Row],[Revenue]]-[1]!Table1[[#This Row],[OperationalCost]] -> #REF! | M11: =TEXT(E11,"MMM") -> Sep | N11: =Table11[[#This Row],[SeatsSold]]/Table11[[#This Row],[SeatsAvailable]] -> 0.83098592 | O11: 45667.229
A12: FL00012 | B12: JAI-HYD | C12: JAI | D12: HYD | E12: 46028 | F12: 101 | G12: Boeing 737 | H12: 200 | I12: 166 | J12: 662174 | K12: 34932 | L12: =[1]!Table1[[#This Row],[Revenue]]-[1]!Table1[[#This Row],[OperationalCost]] -> #REF! | M12: =TEXT(E12,"MMM") -> Jan | N12: =Table11[[#This Row],[SeatsSold]]/Table11[[#This Row],[SeatsAvailable]] -> 0.83 | O12: 45668.229
A13: FL00013 | B13: AMD-BLR | C13: AMD | D13: BLR | E13: 46354 | F13: 153 | G13: Boeing 787 | H13: 86 | I13: 64 | J13: 560128 | K13: 58730 | L13: =[1]!Table1[[#This Row],[Revenue]]-[1]!Table1[[#This Row],[OperationalCost]] -> #REF! | M13: =TEXT(E13,"MMM") -> Nov | N13: =Table11[[#This Row],[SeatsSold]]/Table11[[#This Row],[SeatsAvailable]] -> 0.74418605 | O13: 45669.229 | P13: =DATE(1900,1,1)+E2-2 -> 45687
A14: FL00014 | B14: GOI-MAA | C14: GOI | D14: MAA | E14: 46224 | F14: 47 | G14: Airbus A320 | H14: 207 | I14: 108 | J14: 871884 | K14: 39041 | L14: =[1]!Table1[[#This Row],[Revenue]]-[1]!Table1[[#This Row],[OperationalCost]] -> #REF! | M14: =TEXT(E14,"MMM") -> Jul | N14: =Table11[[#This Row],[SeatsSold]]/Table11[[#This Row],[SeatsAvailable]] -> 0.52173913 | O14: 46023.229
A15: FL00015 | B15: HYD-AMD | C15: HYD | D15: AMD | E15: 46122 | F15: 45 | G15: Airbus A321 | H15: 198 | I15: 85 | J15: 919445 | K15: 54135 | L15: =[1]!Table1[[#This Row],[Revenue]]-[1]!Table1[[#This Row],[OperationalCost]] -> #REF! | M15: =TEXT(E15,"MMM") -> Apr | N15: =Table11[[#This Row],[SeatsSold]]/Table11[[#This Row],[SeatsAvailable]] -> 0.42929293 | O15: 46024.229
A16: FL00016 | B16: MAA-JAI | C16: MAA | D16: JAI | E16: 46281 | F16: 95 | G16: Boeing 737 | H16: 165 | I16: 137 | J16: 705002 | K16: 59985 | L16: =[1]!Table1[[#This Row],[Revenue]]-[1]!Table1[[#This Row],[OperationalCost]] -> #REF! | M16: =TEXT(E16,"MMM") -> Sep | N16: =Table11[[#This Row],[SeatsSold]]/Table11[[#This Row],[SeatsAvailable]] -> 0.83030303 | O16: 46025.229
A17: FL00017 | B17: BOM-HYD | C17: BOM | D17: HYD | E17: 46158 | F17: 49 | G17: Airbus A320 | H17: 162 | I17: 152 | J17: 1145776 | K17: 24097 | L17: =[1]!Table1[[#This Row],[Revenue]]-[1]!Table1[[#This Row],[OperationalCost]] -> #REF! | M17: =TEXT(E17,"MMM") -> May | N17: =Table11[[#This Row],[SeatsSold]]/Table11[[#This Row],[SeatsAvailable]] -> 0.9382716 | O17: 46026.229
A18: FL00018 | B18: BLR-DEL | C18: BLR | D18: DEL | E18: 45745 | F18: 232 | G18: ATR 72 | H18: 87 | I18: 74 | J18: 337440 | K18: 56840 | L18: =[1]!Table1[[#This Row],[Revenue]]-[1]!Table1[[#This Row],[OperationalCost]] -> #REF! | M18: =TEXT(E18,"MMM") -> Mar | N18: =Table11[[#This Row],[SeatsSold]]/Table11[[#This Row],[SeatsAvailable]] -> 0.85057471 | O18: 46027.229
A19: FL00019 | B19: PNQ-JAI | C19: PNQ | D19: JAI | E19: 45827 | F19: 112 | G19: Boeing 787 | H19: 178 | I19: 94 | J19: 1065490 | K19: 56470 | L19: =[1]!Table1[[#This Row],[Revenue]]-[1]!Table1[[#This Row],[OperationalCost]] -> #REF! | M19: =TEXT(E19,"MMM") -> Jun | N19: =Table11[[#This Row],[SeatsSold]]/Table11[[#This Row],[SeatsAvailable]] -> 0.52808989 | O19: 46028.229
A20: FL00020 | B20: MAA-PNQ | C20: MAA | D20: PNQ | E20: 46345 | F20: 211 | G20: Airbus A321 | H20: 182 | I20: 172 | J20: 1702284 | K20: 57676 | L20: =[1]!Table1[[#This Row],[Revenue]]-[1]!Table1[[#This Row],[OperationalCost]] -> #REF! | M20: =TEXT(E20,"MMM") -> Nov | N20: =Table11[[#This Row],[SeatsSold]]/Table11[[#This Row],[SeatsAvailable]] -> 0.94505495 | O20: 46029.229
A21: FL00021 | B21: BLR-DEL | C21: BLR | D21: DEL | E21: 46004 | F21: 50 | G21: Boeing 787 | H21: 211 | I21: 98 | J21: 598584 | K21: 26728 | L21: =[1]!Table1[[#This Row],[Revenue]]-[1]!Table1[[#This Row],[OperationalCost]] -> #REF! | M21: =TEXT(E21,"MMM") -> Dec | N21: =Table11[[#This Row],[SeatsSold]]/Table11[[#This Row],[SeatsAvailable]] -> 0.46445498 | O21: 46030.229
A22: FL00022 | B22: BOM-MAA | C22: BOM | D22: MAA | E22: 45727 | F22: 53 | G22: Airbus A321 | H22: 88 | I22: 72 | J22: 460728 | K22: 28075 | L22: =[1]!Table1[[#This Row],[Revenue]]-[1]!Table1[[#This Row],[OperationalCost]] -> #REF! | M22: =TEXT(E22,"MMM") -> Mar | N22: =Table11[[#This Row],[SeatsSold]]/Table11[[#This Row],[SeatsAvailable]] -> 0.81818182 | O22: 46031.229
A23: FL00023 | B23: BLR-JAI | C23: BLR | D23: JAI | E23: 45793 | F23: 230 | G23: Boeing 787 | H23: 217 | I23: 161 | J23: 1043441 | K23: 95358 | L23: =[1]!Table1[[#This Row],[Revenue]]-[1]!Table1[[#This Row],[OperationalCost]] -> #REF! | M23: =TEXT(E23,"MMM") -> May | N23: =Table11[[#This Row],[SeatsSold]]/Table11[[#This Row],[SeatsAvailable]] -> 0.74193548 | O23: 46032.229
A24: FL00024 | B24: BLR-DEL | C24: BLR | D24: DEL | E24: 45757 | F24: 213 | G24: ATR 72 | H24: 160 | I24: 94 | J24: 868090 | K24: 65787 | L24: =[1]!Table1[[#This Row],[Revenue]]-[1]!Table1[[#This Row],[OperationalCost]] -> #REF! | M24: =TEXT(E24,"MMM") -> Apr | N24: =Table11[[#This Row],[SeatsSold]]/Table11[[#This Row],[SeatsAvailable]] -> 0.5875 | O24: 46033.229
A25: FL00025 | B25: DEL-BOM | C25: DEL | D25: BOM | E25: 46070 | F25: 231 | G25: Airbus A321 | H25: 97 | I25: 55 | J25: 310145 | K25: 59857 | L25: =[1]!Table1[[#This Row],[Revenue]]-[1]!Table1[[#This Row],[OperationalCost]] -> #REF! | M25: =TEXT(E25,"MMM") -> Feb | N25: =Table11[[#This Row],[SeatsSold]]/Table11[[#This Row],[SeatsAvailable]] -> 0.56701031 | O25: 46034.229
A26: FL00026 | B26: PNQ-AMD | C26: PNQ | D26: AMD | E26: 46090 | F26: 91 | G26: Airbus A321 | H26: 188 | I26: 103 | J26: 384705 | K26: 62563 | L26: =[1]!Table1[[#This Row],[Revenue]]-[1]!Table1[[#This Row],[OperationalCost]] -> #REF! | M26: =TEXT(E26,"MMM") -> Mar | N26: =Table11[[#This Row],[SeatsSold]]/Table11[[#This Row],[SeatsAvailable]] -> 0.54787234 | O26: 46388.229
A27: FL00027 | B27: DEL-BOM | C27: DEL | D27: BOM | E27: 46325 | F27: 183 | G27: Airbus A320 | H27: 93 | I27: 88 | J27: 560736 | K27: 46758 | L27: =[1]!Table1[[#This Row],[Revenue]]-[1]!Table1[[#This Row],[OperationalCost]] -> #REF! | M27: =TEXT(E27,"MMM") -> Oct | N27: =Table11[[#This Row],[SeatsSold]]/Table11[[#This Row],[SeatsAvailable]] -> 0.94623656
A28: FL00028 | B28: PNQ-GOI | C28: PNQ | D28: GOI | E28: 45876 | F28: 147 | G28: Airbus A320 | H28: 112 | I28: 88 | J28: 223080 | K28: 48657 | L28: =[1]!Table1[[#This Row],[Revenue]]-[1]!Table1[[#This Row],[OperationalCost]] -> #REF! | M28: =TEXT(E28,"MMM") -> Aug | N28: =Table11[[#This Row],[SeatsSold]]/Table11[[#This Row],[SeatsAvailable]] -> 0.78571429
A29: FL00029 | B29: PNQ-MAA | C29: PNQ | D29: MAA | E29: 46091 | F29: 223 | G29: Boeing 787 | H29: 194 | I29: 79 | J29: 443269 | K29: 69675 | L29: =[1]!Table1[[#This Row],[Revenue]]-[1]!Table1[[#This Row],[OperationalCost]] -> #REF! | M29: =TEXT(E29,"MMM") -> Mar | N29: =Table11[[#This Row],[SeatsSold]]/Table11[[#This Row],[SeatsAvailable]] -> 0.40721649
A30: FL00030 | B30: BOM-JAI | C30: BOM | D30: JAI | E30: 45720 | F30: 236 | G30: Airbus A321 | H30: 84 | I30: 43 | J30: 443373 | K30: 76588 | L30: =[1]!Table1[[#This Row],[Revenue]]-[1]!Table1[[#This Row],[OperationalCost]] -> #REF! | M30: =TEXT(E30,"MMM") -> Mar | N30: =Table11[[#This Row],[SeatsSold]]/Table11[[#This Row],[SeatsAvailable]] -> 0.51190476
A31: FL00031 | B31: AMD-BOM | C31: AMD | D31: BOM | E31: 46178 | F31: 65 | G31: Boeing 737 | H31: 87 | I31: 78 | J31: 281814 | K31: 31160 | L31: =[1]!Table1[[#This Row],[Revenue]]-[1]!Table1[[#This Row],[OperationalCost]] -> #REF! | M31: =TEXT(E31,"MMM") -> Jun | N31: =Table11[[#This Row],[SeatsSold]]/Table11[[#This Row],[SeatsAvailable]] -> 0.89655172
A32: FL00032 | B32: HYD-DEL | C32: HYD | D32: DEL | E32: 46241 | F32: 108 | G32: Boeing 787 | H32: 80 | I32: 79 | J32: 303597 | K32: 44356 | L32: =[1]!Table1[[#This Row],[Revenue]]-[1]!Table1[[#This Row],[OperationalCost]] -> #REF! | M32: =TEXT(E32,"MMM") -> Aug | N32: =Table11[[#This Row],[SeatsSold]]/Table11[[#This Row],[SeatsAvailable]] -> 0.9875 | P32: =DATE(1900,1,1)+E2-2 -> 45687
A33: FL00033 | B33: JAI-GOI | C33: JAI | D33: GOI | E33: 45981 | F33: 111 | G33: Boeing 737 | H33: 150 | I33: 70 | J33: 479570 | K33: 41481 | L33: =[1]!Table1[[#This Row],[Revenue]]-[1]!Table1[[#This Row],[OperationalCost]] -> #REF! | M33: =TEXT(E33,"MMM") -> Nov | N33: =Table11[[#This Row],[SeatsSold]]/Table11[[#This Row],[SeatsAvailable]] -> 0.46666667
A34: FL00034 | B34: MAA-GOI | C34: MAA | D34: GOI | E34: 45981 | F34: 237 | G34: Airbus A320 | H34: 72 | I34: 69 | J34: 808956 | K34: 41421 | L34: =[1]!Table1[[#This Row],[Revenue]]-[1]!Table1[[#This Row],[OperationalCost]] -> #REF! | M34: =TEXT(E34,"MMM") -> Nov | N34: =Table11[[#This Row],[SeatsSold]]/Table11[[#This Row],[SeatsAvailable]] -> 0.95833333 | P34: =TEXT(P32,"mmm yyyy") -> Jan 2025
A35: FL00035 | B35: GOI-BLR | C35: GOI | D35: BLR | E35: 46176 | F35: 112 | G35: Boeing 737 | H35: 159 | I35: 152 | J35: 551304 | K35: 48050 | L35: =[1]!Table1[[#This Row],[Revenue]]-[1]!Table1[[#This Row],[OperationalCost]] -> #REF! | M35: =TEXT(E35,"MMM") -> Jun | N35: =Table11[[#This Row],[SeatsSold]]/Table11[[#This Row],[SeatsAvailable]] -> 0.95597484
A36: FL00036 | B36: MAA-AMD | C36: MAA | D36: AMD | E36: 46106 | F36: 184 | G36: Airbus A321 | H36: 205 | I36: 42 | J36: 486612 | K36: 87109 | L36: =[1]!Table1[[#This Row],[Revenue]]-[1]!Table1[[#This Row],[OperationalCost]] -> #REF! | M36: =TEXT(E36,"MMM") -> Mar | N36: =Table11[[#This Row],[SeatsSold]]/Table11[[#This Row],[SeatsAvailable]] -> 0.20487805
A37: FL00037 | B37: DEL-BLR | C37: DEL | D37: BLR | E37: 45928 | F37: 74 | G37: Airbus A320 | H37: 211 | I37: 79 | J37: 549998 | K37: 63582 | L37: =[1]!Table1[[#This Row],[Revenue]]-[1]!Table1[[#This Row],[OperationalCost]] -> #REF! | M37: =TEXT(E37,"MMM") -> Sep | N37: =Table11[[#This Row],[SeatsSold]]/Table11[[#This Row],[SeatsAvailable]] -> 0.37440758 | P37: =YEAR(E2)&"-"&MONTH(E2) -> 2025-1
A38: FL00038 | B38: BLR-HYD | C38: BLR | D38: HYD | E38: 45866 | F38: 220 | G38: Airbus A321 | H38: 199 | I38: 165 | J38: 1091310 | K38: 49757 | L38: =[1]!Table1[[#This Row],[Revenue]]-[1]!Table1[[#This Row],[OperationalCost]] -> #REF! | M38: =TEXT(E38,"MMM") -> Jul | N38: =Table11[[#This Row],[SeatsSold]]/Table11[[#This Row],[SeatsAvailable]] -> 0.82914573
A39: FL00039 | B39: HYD-MAA | C39: HYD | D39: MAA | E39: 45703 | F39: 45 | G39: Airbus A321 | H39: 103 | I39: 73 | J39: 375731 | K39: 33248 | L39: =[1]!Table1[[#This Row],[Revenue]]-[1]!Table1[[#This Row],[OperationalCost]] -> #REF! | M39: =TEXT(E39,"MMM") -> Feb | N39: =Table11[[#This Row],[SeatsSold]]/Table11[[#This Row],[SeatsAvailable]] -> 0.70873786
A40: FL00040 | B40: HYD-JAI | C40: HYD | D40: JAI | E40: 45667 | F40: 73 | G40: Airbus A320 | H40: 108 | I40: 44 | J40: 376156 | K40: 43505 | L40: =[1]!Table1[[#This Row],[Revenue]]-[1]!Table1[[#This Row],[OperationalCost]] -> #REF! | M40: =TEXT(E40,"MMM") -> Jan | N40: =Table11[[#This Row],[SeatsSold]]/Table11[[#This Row],[SeatsAvailable]] -> 0.40740741
...
